<?xml version="1.0" ?>
<!-- =================================================================================== -->
<!-- |    This document was autogenerated by xacro from robot.xacro                    | -->
<!-- |    EDITING THIS FILE BY HAND IS NOT RECOMMENDED                                 | -->
<!-- =================================================================================== -->
<robot name="z1_gripper">
  <link name="link6">
    <visual>
      <origin rpy="0 0 0" xyz="0 0 0"/>
      <geometry>
        <mesh filename="package://robots/meshes/visual/z1_link6.obj" scale="1 1 1"/>
      </geometry>
      <material name="silver">
        <color rgba="0.75 0.75 0.75 1."/>
      </material>
    </visual>
    <collision>
      <origin rpy="0 0 0" xyz="0 0 0"/>
      <geometry>
        <mesh filename="package://robots/meshes/collision/z1_link6.STL" scale="1 1 1"/>
      </geometry>
    </collision>
    <inertial>
      <origin rpy="0 0 0" xyz="0.0241569 -0.00017355 -0.00143876"/>
      <mass value="0.28875807"/>
      <inertia ixx="0.00018328" ixy="1.22e-06" ixz="5.4e-07" iyy="0.0001475" iyz="8e-08" izz="0.0001468"/>
    </inertial>
  </link>

  <joint name="gripperStator" type="fixed">
    <origin rpy="0 0 0" xyz="0.051 0.0 0.0"/>
    <parent link="link6"/>
    <child link="gripperStator"/>
  </joint>

  <link name="gripperStator">
    <visual>
      <origin rpy="0 0 0" xyz="0 0 0"/>
      <geometry>
        <mesh filename="package://robots/meshes/visual/z1_gripper_stator.obj" scale="1 1 1"/>
      </geometry>
      <material name="gray">
        <color rgba="0.3 0.3 0.3 1."/>
      </material>
    </visual>
    <collision>
      <geometry>
        <mesh filename="package://robots/meshes/collision/z1_gripper_stator.STL" scale="1 1 1"/>
      </geometry>
    </collision>
    <inertial>
      <origin rpy="0 0 0" xyz="0.04764427 -0.00035819 -0.00249162"/>
      <mass value="0.52603655"/>
      <inertia ixx="0.00038683" ixy="-3.59e-06" ixz="7.662e-05" iyy="0.00068614" iyz="2.09e-06" izz="0.00066293"/>
    </inertial>
  </link>
  
  <joint name="jointGripper" type="revolute">
    <origin rpy="0 0 0" xyz="0.049 0.0 0"/>
    <parent link="gripperStator"/>
    <child link="gripperMover"/>
    <axis xyz="0 1 0"/>
    <dynamics damping="1.0" friction="1.0"/>
    <limit effort="30.0" lower="-1.5707963267948966" upper="0.0" velocity="3.1415"/>
  </joint>
  
  <link name="gripperMover">
    <visual>
      <origin rpy="0 0 0" xyz="0 0 0"/>
      <geometry>
        <mesh filename="package://robots/meshes/visual/z1_gripper_mover.obj" scale="1 1 1"/>
      </geometry>
      <material name="gray">
        <color rgba="0.3 0.3 0.3 1."/>
      </material>
    </visual>
    <collision>
      <geometry>
        <mesh filename="package://robots/meshes/collision/z1_gripper_mover.STL" scale="1 1 1"/>
      </geometry>
    </collision>
    <inertial>
      <origin rpy="0 0 0" xyz="0.01320633 0.00476708 0.00380534"/>
      <mass value="0.27621302"/>
      <inertia ixx="0.00017716" ixy="1.683e-05" ixz="-1.786e-05" iyy="0.00026787" iyz="2.62e-06" izz="0.00035728"/>
    </inertial>
  </link>

  <link name="tcp_link">
    <!-- <visual>
      <origin rpy="0 0 0" xyz="0 0 0"/>
      <geometry>
        <sphere radius="0.01"/>
      </geometry>
      <material name="red">
        <color rgba="1. 0. 0. 1."/>
      </material>
    </visual> -->
    <inertial>
        <origin rpy="0 0 0" xyz="0 0 0"/>
        <mass value="1e-10"/>
        <inertia ixx="1e-10" ixy="0" ixz="0" iyy="1e-10" iyz="0" izz="1e-10"/>
    </inertial>
  </link>

  <joint name="tcp_joint" type="fixed">
    <origin rpy="0 0 0" xyz="0.19 0.0 -0.01"/>
    <parent link="link6"/>
    <child link="tcp_link"/>
  </joint>
</robot>